2025-09-14 23:31:28.838 | None | ERROR    | process [25496] | thread [27060] | logging:callHandlers:1762 - Traceback (most recent call last):
  File "C:\Users\sudal\AppData\Roaming\uv\python\cpython-3.12.11-windows-x86_64-none\Lib\asyncio\runners.py", line 195, in run
    return runner.run(main)
           ^^^^^^^^^^^^^^^^
  File "C:\Users\sudal\AppData\Roaming\uv\python\cpython-3.12.11-windows-x86_64-none\Lib\asyncio\runners.py", line 118, in run
    return self._loop.run_until_complete(task)
           ^^^^^^^^^^^^^^^^^^^^^^^^^^^^^^^^^^^
  File "C:\Users\sudal\AppData\Roaming\uv\python\cpython-3.12.11-windows-x86_64-none\Lib\asyncio\base_events.py", line 678, in run_until_complete
    self.run_forever()
  File "C:\Users\sudal\AppData\Roaming\uv\python\cpython-3.12.11-windows-x86_64-none\Lib\asyncio\windows_events.py", line 322, in run_forever
    super().run_forever()
  File "C:\Users\sudal\AppData\Roaming\uv\python\cpython-3.12.11-windows-x86_64-none\Lib\asyncio\base_events.py", line 645, in run_forever
    self._run_once()
  File "C:\Users\sudal\AppData\Roaming\uv\python\cpython-3.12.11-windows-x86_64-none\Lib\asyncio\base_events.py", line 1999, in _run_once
    handle._run()
  File "C:\Users\sudal\AppData\Roaming\uv\python\cpython-3.12.11-windows-x86_64-none\Lib\asyncio\events.py", line 88, in _run
    self._context.run(self._callback, *self._args)
  File "D:\file\projects\python_project\p\fast-api-demo\.venv\Lib\site-packages\uvicorn\server.py", line 70, in serve
    with self.capture_signals():
         ^^^^^^^^^^^^^^^^^^^^^^
  File "C:\Users\sudal\AppData\Roaming\uv\python\cpython-3.12.11-windows-x86_64-none\Lib\contextlib.py", line 144, in __exit__
    next(self.gen)
  File "D:\file\projects\python_project\p\fast-api-demo\.venv\Lib\site-packages\uvicorn\server.py", line 331, in capture_signals
    signal.raise_signal(captured_signal)
  File "C:\Users\sudal\AppData\Roaming\uv\python\cpython-3.12.11-windows-x86_64-none\Lib\asyncio\runners.py", line 157, in _on_sigint
    raise KeyboardInterrupt()
KeyboardInterrupt

During handling of the above exception, another exception occurred:

Traceback (most recent call last):
  File "D:\file\projects\python_project\p\fast-api-demo\.venv\Lib\site-packages\starlette\routing.py", line 701, in lifespan
    await receive()
  File "D:\file\projects\python_project\p\fast-api-demo\.venv\Lib\site-packages\uvicorn\lifespan\on.py", line 137, in receive
    return await self.receive_queue.get()
           ^^^^^^^^^^^^^^^^^^^^^^^^^^^^^^
  File "C:\Users\sudal\AppData\Roaming\uv\python\cpython-3.12.11-windows-x86_64-none\Lib\asyncio\queues.py", line 158, in get
    await getter
asyncio.exceptions.CancelledError

